[MFLOG|0|2022-11-01T20:11:08.139219Z|runtime|5c384292-f3df-44ba-b80d-6079795bdf7d]<flow SampleRegressionFlow step train_model> failed:
[MFLOG|0|2022-11-01T20:11:08.143141Z|runtime|2f8b7562-9478-4290-adfc-e4cc42b327d9]    Internal error
[MFLOG|0|2022-11-01T20:11:08.143652Z|runtime|f8ce465b-ade7-4f0f-9fe3-3dea5e2881f1]Traceback (most recent call last):
[MFLOG|0|2022-11-01T20:11:08.143689Z|runtime|51f5e4c4-86d9-4829-817c-25b168c759dd]  File "/Users/qinyixin/opt/anaconda3/lib/python3.9/site-packages/metaflow/cli.py", line 1110, in main
[MFLOG|0|2022-11-01T20:11:08.143758Z|runtime|9bb67c93-f139-4ecb-8523-7a135199c1a3]    start(auto_envvar_prefix="METAFLOW", obj=state)
[MFLOG|0|2022-11-01T20:11:08.143789Z|runtime|158f38dc-09a1-4611-93fb-0327951ceca7]  File "/Users/qinyixin/opt/anaconda3/lib/python3.9/site-packages/click/core.py", line 1128, in __call__
[MFLOG|0|2022-11-01T20:11:08.143826Z|runtime|96f198b7-eb82-4921-bf66-2ab6ad8d02c5]    return self.main(args, kwargs)
[MFLOG|0|2022-11-01T20:11:08.143857Z|runtime|8d4ee515-6e6b-4c62-bbcf-ba89c402352f]  File "/Users/qinyixin/opt/anaconda3/lib/python3.9/site-packages/click/core.py", line 1053, in main
[MFLOG|0|2022-11-01T20:11:08.143885Z|runtime|854455ea-4435-42e0-ac5f-628e2676c425]    rv = self.invoke(ctx)
[MFLOG|0|2022-11-01T20:11:08.143910Z|runtime|b2404148-6edd-42a4-9ecc-91722c3b3174]  File "/Users/qinyixin/opt/anaconda3/lib/python3.9/site-packages/click/core.py", line 1659, in invoke
[MFLOG|0|2022-11-01T20:11:08.143938Z|runtime|fd8785a8-4b98-4883-a8e9-9bdcf3c7634e]    return _process_result(sub_ctx.command.invoke(sub_ctx))
[MFLOG|0|2022-11-01T20:11:08.143962Z|runtime|39b784ce-f3ed-4a77-be12-7bdce2256766]  File "/Users/qinyixin/opt/anaconda3/lib/python3.9/site-packages/click/core.py", line 1395, in invoke
[MFLOG|0|2022-11-01T20:11:08.143987Z|runtime|f4c3baae-55a5-41c5-8b72-43c6379a2318]    return ctx.invoke(self.callback, ctx.params)
[MFLOG|0|2022-11-01T20:11:08.144012Z|runtime|aade7723-634e-4a87-b19a-96a730a2bdfa]  File "/Users/qinyixin/opt/anaconda3/lib/python3.9/site-packages/click/core.py", line 754, in invoke
[MFLOG|0|2022-11-01T20:11:08.144037Z|runtime|0906a1c3-5827-4c8c-bdb9-95abee0a2edd]    return __callback(args, kwargs)
[MFLOG|0|2022-11-01T20:11:08.235150Z|runtime|55788f58-8f24-422b-8fea-f5a6b550302b]  File "/Users/qinyixin/opt/anaconda3/lib/python3.9/site-packages/click/decorators.py", line 26, in new_func
[MFLOG|0|2022-11-01T20:11:08.235302Z|runtime|51fac274-95c8-4476-b6b4-0de3dfb73f69]    return f(get_current_context(), args, kwargs)
[MFLOG|0|2022-11-01T20:11:08.235335Z|runtime|a24184ef-3c79-4a22-b8f9-01b720a4c42d]  File "/Users/qinyixin/opt/anaconda3/lib/python3.9/site-packages/metaflow/cli.py", line 544, in step
[MFLOG|0|2022-11-01T20:11:08.235359Z|runtime|75a857ec-4bba-4794-ae50-1de9d0fd6cb0]    task.run_step(
[MFLOG|0|2022-11-01T20:11:08.235382Z|runtime|79cbdd39-bdc6-4f62-9381-99cfbc417230]  File "/Users/qinyixin/opt/anaconda3/lib/python3.9/site-packages/metaflow/task.py", line 547, in run_step
[MFLOG|0|2022-11-01T20:11:08.235408Z|runtime|b213b2be-ffa9-47bb-9c2a-11c8ea7fb6ba]    self._exec_step_function(step_func)
[MFLOG|0|2022-11-01T20:11:08.235431Z|runtime|7f4aa7bf-33ee-4932-b28f-5e1e53b1f14b]  File "/Users/qinyixin/opt/anaconda3/lib/python3.9/site-packages/metaflow/task.py", line 53, in _exec_step_function
[MFLOG|0|2022-11-01T20:11:08.235453Z|runtime|4587787d-437c-4d1a-b8d7-e2e21e5c707c]    step_function()
[MFLOG|0|2022-11-01T20:11:08.235475Z|runtime|2f4d557c-cc20-46c6-828a-5b7630f9ba87]  File "/Users/qinyixin/Desktop/7773_assignement/flow_3.py", line 106, in train_model
[MFLOG|0|2022-11-01T20:11:08.235497Z|runtime|861e0618-a477-426e-bab8-a8e1042acd9e]    reg.fit(self.x_train, self.y_train)
[MFLOG|0|2022-11-01T20:11:08.235518Z|runtime|658ab23a-1c29-46a7-acdf-bddbfbef1f29]  File "/Users/qinyixin/opt/anaconda3/lib/python3.9/site-packages/comet_ml/monkey_patching.py", line 312, in wrapper
[MFLOG|0|2022-11-01T20:11:08.235540Z|runtime|07efb604-9564-42a1-b697-fd62190b13cb]    return_value = original(args, kwargs)
[MFLOG|0|2022-11-01T20:11:08.235562Z|runtime|9611f428-a866-4f5a-a8d6-35f6c5c8c441]  File "/Users/qinyixin/opt/anaconda3/lib/python3.9/site-packages/sklearn/svm/_classes.py", line 254, in fit
[MFLOG|0|2022-11-01T20:11:08.235584Z|runtime|e17d6d79-e618-4274-ad70-2fab01fadc8d]    check_classification_targets(y)
[MFLOG|0|2022-11-01T20:11:08.235605Z|runtime|05c8af96-23df-4df7-abcd-b335193b5fa7]  File "/Users/qinyixin/opt/anaconda3/lib/python3.9/site-packages/sklearn/utils/multiclass.py", line 197, in check_classification_targets
[MFLOG|0|2022-11-01T20:11:08.235638Z|runtime|8336e1aa-773d-4bb5-86b6-e2b6fd7bb5d9]    raise ValueError("Unknown label type: %r" % y_type)
[MFLOG|0|2022-11-01T20:11:08.235659Z|runtime|fd54379a-4e28-471d-a426-dfcf29038c1d]ValueError: Unknown label type: 'continuous'
[MFLOG|0|2022-11-01T20:11:08.235692Z|runtime|8364b699-c8e7-4d88-9974-efb029e911c7]
[MFLOG|0|2022-11-01T20:11:08.236060Z|runtime|f16eb56c-60af-49e8-8636-3dc3063fb652]Task failed.