[MFLOG|0|2022-11-01T20:28:56.271924Z|runtime|031ce205-7cfa-444a-993b-2459b6a2a9c1]<flow SVMFlow step train_model[1] (input: 200)> failed:
[MFLOG|0|2022-11-01T20:28:56.277690Z|runtime|c9c6c78a-af6f-4239-9726-2c573a3b930c]    Internal error
[MFLOG|0|2022-11-01T20:28:56.279352Z|runtime|821b0fdd-3f5c-412d-9813-bbe1ae3413a4]Traceback (most recent call last):
[MFLOG|0|2022-11-01T20:28:56.473357Z|runtime|92ec7884-941d-4153-9fea-b4e3989f0fa8]  File "/Users/qinyixin/opt/anaconda3/lib/python3.9/site-packages/metaflow/cli.py", line 1110, in main
[MFLOG|0|2022-11-01T20:28:56.473523Z|runtime|c22b9442-9368-4513-b21a-0569fc6ef3a7]    start(auto_envvar_prefix="METAFLOW", obj=state)
[MFLOG|0|2022-11-01T20:28:56.473562Z|runtime|74c35b66-7134-4d83-bf40-fbc8fe6ed9f0]  File "/Users/qinyixin/opt/anaconda3/lib/python3.9/site-packages/click/core.py", line 1128, in __call__
[MFLOG|0|2022-11-01T20:28:56.473587Z|runtime|12ad163b-993b-45e3-9c00-fb1c5e0e36d4]    return self.main(args, kwargs)
[MFLOG|0|2022-11-01T20:28:56.473610Z|runtime|1264f657-77ae-4dae-98df-45aa71b177a6]  File "/Users/qinyixin/opt/anaconda3/lib/python3.9/site-packages/click/core.py", line 1053, in main
[MFLOG|0|2022-11-01T20:28:56.473636Z|runtime|7e6ca792-e628-4a02-b5e6-bf8d26dc2ef9]    rv = self.invoke(ctx)
[MFLOG|0|2022-11-01T20:28:56.473702Z|runtime|65162ffd-8fea-4d9d-8777-a97da0352cc9]  File "/Users/qinyixin/opt/anaconda3/lib/python3.9/site-packages/click/core.py", line 1659, in invoke
[MFLOG|0|2022-11-01T20:28:56.473802Z|runtime|41abdd4c-95c9-476c-84b2-5890bbd9d46e]    return _process_result(sub_ctx.command.invoke(sub_ctx))
[MFLOG|0|2022-11-01T20:28:56.473834Z|runtime|70f0aa81-88cc-4e46-b36e-a20a41bab02d]  File "/Users/qinyixin/opt/anaconda3/lib/python3.9/site-packages/click/core.py", line 1395, in invoke
[MFLOG|0|2022-11-01T20:28:56.473859Z|runtime|c310a3f1-5171-4508-b410-e288f78dbcbd]    return ctx.invoke(self.callback, ctx.params)
[MFLOG|0|2022-11-01T20:28:56.473881Z|runtime|bc146dcc-81e7-401e-b6ac-66e97d6aaf31]  File "/Users/qinyixin/opt/anaconda3/lib/python3.9/site-packages/click/core.py", line 754, in invoke
[MFLOG|0|2022-11-01T20:28:56.473911Z|runtime|a5adc40b-02a0-4251-b55b-63c6bf6138d5]    return __callback(args, kwargs)
[MFLOG|0|2022-11-01T20:28:56.473933Z|runtime|fb259849-2283-4415-9942-30a39aa13b1a]  File "/Users/qinyixin/opt/anaconda3/lib/python3.9/site-packages/click/decorators.py", line 26, in new_func
[MFLOG|0|2022-11-01T20:28:56.473958Z|runtime|c62fc101-6b97-4b4f-b20c-195c5f739544]    return f(get_current_context(), args, kwargs)
[MFLOG|0|2022-11-01T20:28:56.473980Z|runtime|32bc7839-a3b3-46b4-bc04-4868f17fd77a]  File "/Users/qinyixin/opt/anaconda3/lib/python3.9/site-packages/metaflow/cli.py", line 544, in step
[MFLOG|0|2022-11-01T20:28:56.474002Z|runtime|a3d091eb-af6c-4366-b7fa-5c4b9e847681]    task.run_step(
[MFLOG|0|2022-11-01T20:28:56.474027Z|runtime|70e48927-f89c-4a5b-8494-fb9cd91fe83b]  File "/Users/qinyixin/opt/anaconda3/lib/python3.9/site-packages/metaflow/task.py", line 547, in run_step
[MFLOG|0|2022-11-01T20:28:56.474049Z|runtime|8049422b-7b96-4dfc-8f17-44ea12cdc3ad]    self._exec_step_function(step_func)
[MFLOG|0|2022-11-01T20:28:56.474119Z|runtime|bf5ba643-04bf-4af9-a754-c668baf97779]  File "/Users/qinyixin/opt/anaconda3/lib/python3.9/site-packages/metaflow/task.py", line 53, in _exec_step_function
[MFLOG|0|2022-11-01T20:28:56.474187Z|runtime|649d56da-a9b5-4970-b276-88503912bd6d]    step_function()
[MFLOG|0|2022-11-01T20:28:56.474215Z|runtime|c7aeb184-f6bc-4c04-acd8-f3a7c616285f]  File "/Users/qinyixin/Desktop/7773_assignement/flow_2.py", line 121, in train_model
[MFLOG|0|2022-11-01T20:28:56.474261Z|runtime|d6f0b6af-186f-41ae-bc32-54cd0e41d802]    reg.fit(self.x_train, self.y_train)
[MFLOG|0|2022-11-01T20:28:56.474297Z|runtime|ad012f73-6cc2-498f-8d94-5c33f5719af6]  File "/Users/qinyixin/opt/anaconda3/lib/python3.9/site-packages/comet_ml/monkey_patching.py", line 312, in wrapper
[MFLOG|0|2022-11-01T20:28:56.474322Z|runtime|f1b17c80-90b9-4564-b3e8-30f937462aba]    return_value = original(args, kwargs)
[MFLOG|0|2022-11-01T20:28:56.474345Z|runtime|27c628c9-5298-4947-8a0c-f6fc05e23a77]  File "/Users/qinyixin/opt/anaconda3/lib/python3.9/site-packages/sklearn/linear_model/_bayes.py", line 233, in fit
[MFLOG|0|2022-11-01T20:28:56.474368Z|runtime|88267e44-a734-4519-b0ec-a034e612e3a9]    if self.n_iter < 1:
[MFLOG|0|2022-11-01T20:28:56.474390Z|runtime|98e7c9b5-dea7-44ac-be91-b8310d235853]TypeError: '<' not supported between instances of 'builtin_function_or_method' and 'int'
[MFLOG|0|2022-11-01T20:28:56.474412Z|runtime|10cefda1-5010-41a6-848c-23291de201f6]
[MFLOG|0|2022-11-01T20:28:56.475034Z|runtime|c9299a22-0443-4ab6-aeb1-4c5b058a2d4f]Task failed.